[WARNING] - pyrogram.storage.memory_storage - You are using an old session string format. Use export_session_string to update
[ERROR] - pyrogram.dispatcher - 
Traceback (most recent call last):
  File "/home/codespace/.python/current/lib/python3.10/asyncio/locks.py", line 214, in wait
    await fut
asyncio.exceptions.CancelledError

During handling of the above exception, another exception occurred:

Traceback (most recent call last):
  File "/home/codespace/.python/current/lib/python3.10/asyncio/tasks.py", line 456, in wait_for
    return fut.result()
asyncio.exceptions.CancelledError

The above exception was the direct cause of the following exception:

Traceback (most recent call last):
  File "/home/codespace/.local/lib/python3.10/site-packages/pyrogram/dispatcher.py", line 240, in handler_worker
    await handler.callback(self.client, *args)
  File "/home/codespace/.python/current/lib/python3.10/site-packages/pytgcalls/mtproto/pyrogram_bridge.py", line 72, in _process_update
    await self._update_to_handler[type(update)](update)
  File "/home/codespace/.python/current/lib/python3.10/site-packages/pytgcalls/mtproto/pyrogram_bridge.py", line 78, in _process_group_call_participants_update
    await self.group_call_participants_update_callback(wrapped_update)
  File "/home/codespace/.python/current/lib/python3.10/site-packages/pytgcalls/implementation/group_call_base.py", line 139, in _group_call_participants_update_callback
    await self.reconnect()
  File "/home/codespace/.python/current/lib/python3.10/site-packages/pytgcalls/implementation/group_call_base.py", line 333, in reconnect
    await asyncio.wait_for(self.__emit_join_payload_event.wait(), timeout=self.__ASYNCIO_TIMEOUT)
  File "/home/codespace/.python/current/lib/python3.10/asyncio/tasks.py", line 458, in wait_for
    raise exceptions.TimeoutError() from exc
asyncio.exceptions.TimeoutError
[ERROR] - pyrogram.dispatcher - 
Traceback (most recent call last):
  File "/home/codespace/.python/current/lib/python3.10/asyncio/locks.py", line 214, in wait
    await fut
asyncio.exceptions.CancelledError

During handling of the above exception, another exception occurred:

Traceback (most recent call last):
  File "/home/codespace/.python/current/lib/python3.10/asyncio/tasks.py", line 456, in wait_for
    return fut.result()
asyncio.exceptions.CancelledError

The above exception was the direct cause of the following exception:

Traceback (most recent call last):
  File "/home/codespace/.local/lib/python3.10/site-packages/pyrogram/dispatcher.py", line 240, in handler_worker
    await handler.callback(self.client, *args)
  File "/home/codespace/.python/current/lib/python3.10/site-packages/pytgcalls/mtproto/pyrogram_bridge.py", line 72, in _process_update
    await self._update_to_handler[type(update)](update)
  File "/home/codespace/.python/current/lib/python3.10/site-packages/pytgcalls/mtproto/pyrogram_bridge.py", line 78, in _process_group_call_participants_update
    await self.group_call_participants_update_callback(wrapped_update)
  File "/home/codespace/.python/current/lib/python3.10/site-packages/pytgcalls/implementation/group_call_base.py", line 139, in _group_call_participants_update_callback
    await self.reconnect()
  File "/home/codespace/.python/current/lib/python3.10/site-packages/pytgcalls/implementation/group_call_base.py", line 333, in reconnect
    await asyncio.wait_for(self.__emit_join_payload_event.wait(), timeout=self.__ASYNCIO_TIMEOUT)
  File "/home/codespace/.python/current/lib/python3.10/asyncio/tasks.py", line 458, in wait_for
    raise exceptions.TimeoutError() from exc
asyncio.exceptions.TimeoutError
